Workbook

Sheet Master
A1: Golf Betting Record - Outright
A2: Tour/Majors | B2: Tour/Majors
A3: Date (Year) | B3: DP World Tour | C3: LIV | D3: Majors | E3: Multiple | F3: Olympics | G3: PGA Tour | H3: Ryder Cup | I3: Grand Total
A4: 44927 | B4: 296.59 | C4: 120 | D4: -7.5 | E4: -21.35 | H4: 63.25 | I4: 450.99
A5: 45292 | B5: -72.47 | C5: -107.9 | D5: 156.06 | E5: -48.18 | F5: -24.37 | G5: 301.52 | I5: 204.66
A6: 45658 | B6: 27.5 | C6: -30 | D6: 111.35 | E6: -54 | G6: 307.15 | H6: 42.5 | I6: 404.5
A7: 46023 | E7: -20 | I7: -20
A8: Grand Total | B8: 251.62 | C8: -17.9 | D8: 259.91 | E8: -143.53 | F8: -24.37 | G8: 608.67 | H8: 105.75 | I8: 1040.15
J10: Overall - Combined Outright & multiples
J11: Category | K11: Total
J12: DP World Tour | K12: 251.62
J13: LIV | K13: -17.9
J14: Majors | K14: 259.91
J15: PGA Tour | K15: 608.67
J16: Ryder Cup | K16: 105.75
J17: Multiple | K17: -143.53
J18: Olympics | K18: -24.37
K19: {=SUM(K12:K18)} -> 1040.15
L21: Monthly ROI%
L22: Month | M22: Return On Investment
L23: 45078 | M23: 1.125
L24: 45108 | M24: -0.75181818
L25: 45170 | M25: 4.657602
L26: 45200 | M26: -1
L27: 45352 | M27: 4.4586667
L28: 45383 | M28: -0.0085432099
L29: 45413 | M29: -0.23770115
L30: 45444 | M30: 1.0022472
L31: 45474 | M31: 0.49833962
L32: 45505 | M32: 0.62256358
L33: 45536 | M33: -0.85327869
L34: 45566 | M34: -0.36660494
... L46: 45992 | M46: 0.53537736

Sheet Overall
A1: Date | B1: Tour/Majors | C1: Tournament | D1: Course | E1: Course Details | F1: Player | G1: Pre/Mid Tournament | H1: Type | I1: Price | J1: Place Terms | K1: Stake | L1: Bookmaker | M1: Result | N1: Outcome | O1: Return | P1: Profit/Loss | Q1: Tournament Winner | R1: Tournament Winner Odds | S1: Pre Tournament Notes | T1: Post Tournament Notes
A2: 09/07/2026 | B2: PGA Tour | C2: ISCO Championship | D2: Hurstbourne Country Club | E2: Course Hurstbourne Country Club, Louisville, Kentucky Length 7,056 yards Par 70 Course make-up two par-fives; 12 par-fours; four par-threes Course type Parkland Grass type Fairways: Meyer Zoysiagrass; Rough: Kentucky Bluegrass with Fine Fescue 4-6″; Greens: 4,750 sq.ft average featuring A1/A4 Bentgrass; Stimpmeter: 11ft. Course overview Keene Trace staged this event (previously called the Barbasol Championship) from 2018 to last year. The 2020 edition was cancelled due to Covid. Hurstbourne Country Club takes over for the first time this year. This short, tree-lined layout relies on water hazards and small greens to keep scoring in check. The fairways are zoysia grass and the greens are bentgrass. What will it take to win? This short, fiddly layout commands accurate approaches and smart scrambling around small greens | F2: Stephen Jaeger | G2: Pre | H2: First Round Leader E/W | I2: 45-1 | J2: N/A | K2: 5 | L2: Bet365 | M2: T1 | N2: Win | O2: 59.38 | P2: =SUM(O2-K2) -> 54.38 | Q2: Pending | R2: Pending | S2: Pending | T2: Pending
A3: 08/07/2026 | B3: DP World Tour | C3: Genesis Scottish Open | D3: The Renaissance Club | E3: Course The Renaissance Club, North Berwick, East Lothian, Scotland Length 7,282 yards Par 70 Course make-up Three par-fives; ten par-fours; five par-threes Course type Links Grass type Greens are fescue-based, similar to those used at Castle Stuart in this event in the relatively recent past, as well as at Royal Birkdale for the 2017 Open Championship. Course overview The Renaissance Club, which opened in 2008, was designed by Tom Doak. It made its Scottish Open debut in 2019, hosting every year since. Three holes run directly along the Firth of Forth, but this is not a pure links test, with some trees in strategic fairway and greenside positions. Heavily contoured greens are the main defence of the course What will it take to win? A strong short-game is a great asset on and around tricky greens. | F3: Davis Riley | G3: Pre | H3: First Round Leader E/W | I3: 325-1 | J3: 1/4 Top 5 | K3: 2.5 | L3: Coral | M3: N/A | N3: Loss | O3: 0 | P3: =SUM(O3-K3) -> -2.5 | Q3: Pending | R3: Pending | S3: Pending | T3: Pending
A4: 08/07/2026 | B4: DP World Tour | C4: Genesis Scottish Open | D4: The Renaissance Club | E4: Course The Renaissance Club, North Berwick, East Lothian, Scotland Length 7,282 yards Par 70 Course make-up Three par-fives; ten par-fours; five par-threes Course type Links Grass type Greens are fescue-based, similar to those used at Castle Stuart in this event in the relatively recent past, as well as at Royal Birkdale for the 2017 Open Championship. Course overview The Renaissance Club, which opened in 2008, was designed by Tom Doak. It made its Scottish Open debut in 2019, hosting every year since. Three holes run directly along the Firth of Forth, but this is not a pure links test, with some trees in strategic fairway and greenside positions. Heavily contoured greens are the main defence of the course What will it take to win? A strong short-game is a great asset on and around tricky greens. | F4: Calum Hill | G4: Pre | H4: First Round Leader E/W | I4: 140-1 | J4: 1/4 Top 5 | K4: 2.5 | L4: Coral | M4: N/A | N4: Loss | O4: 0 | P4: =SUM(O4-K4) -> -2.5 | Q4: Pending | R4: Pending | S4: Pending | T4: Pending
A5: 08/07/2026 | B5: DP World Tour | C5: Genesis Scottish Open | D5: The Renaissance Club | E5: Course The Renaissance Club, North Berwick, East Lothian, Scotland Length 7,282 yards Par 70 Course make-up Three par-fives; ten par-fours; five par-threes Course type Links Grass type Greens are fescue-based, similar to those used at Castle Stuart in this event in the relatively recent past, as well as at Royal Birkdale for the 2017 Open Championship. Course overview The Renaissance Club, which opened in 2008, was designed by Tom Doak. It made its Scottish Open debut in 2019, hosting every year since. Three holes run directly along the Firth of Forth, but this is not a pure links test, with some trees in strategic fairway and greenside positions. Heavily contoured greens are the main defence of the course What will it take to win? A strong short-game is a great asset on and around tricky greens. | F5: Wyndham Clark | G5: Pre | H5: First Round Leader E/W | I5: 45-1 | J5: 1/4 Top 5 | K5: 2.5 | L5: Coral | M5: N/A | N5: Loss | O5: 0 | P5: =SUM(O5-K5) -> -2.5 | Q5: Pending | R5: Pending | S5: Pending | T5: Pending
A6: 07/07/2026 | B6: PGA Tour | C6: ISCO Championship | D6: Hurstbourne Country Club | E6: Course Hurstbourne Country Club, Louisville, Kentucky Length 7,056 yards Par 70 Course make-up two par-fives; 12 par-fours; four par-threes Course type Parkland Grass type Fairways: Meyer Zoysiagrass; Rough: Kentucky Bluegrass with Fine Fescue 4-6″; Greens: 4,750 sq.ft average featuring A1/A4 Bentgrass; Stimpmeter: 11ft. Course overview Keene Trace staged this event (previously called the Barbasol Championship) from 2018 to last year. The 2020 edition was cancelled due to Covid. Hurstbourne Country Club takes over for the first time this year. This short, tree-lined layout relies on water hazards and small greens to keep scoring in check. The fairways are zoysia grass and the greens are bentgrass. What will it take to win? This short, fiddly layout commands accurate approaches and smart scrambling around small greens | F6: Max Homa | G6: Pre | H6: Outright | I6: 17-1 | J6: N/A | K6: 10 | L6: Bet365 | M6: Pending | N6: Pending | O6: 0 | P6: =SUM(O6-K6) -> -10 | Q6: Pending | R6: Pending | S6: Pending | T6: Pending
A7: 06/07/2026 | B7: DP World Tour | C7: Genesis Scottish Open | D7: The Renaissance Club | E7: Course The Renaissance Club, North Berwick, East Lothian, Scotland Length 7,282 yards Par 70 Course make-up Three par-fives; ten par-fours; five par-threes Course type Links Grass type Greens are fescue-based, similar to those used at Castle Stuart in this event in the relatively recent past, as well as at Royal Birkdale for the 2017 Open Championship. Course overview The Renaissance Club, which opened in 2008, was designed by Tom Doak. It made its Scottish Open debut in 2019, hosting every year since. Three holes run directly along the Firth of Forth, but this is not a pure links test, with some trees in strategic fairway and greenside positions. Heavily contoured greens are the main defence of the course What will it take to win? A strong short-game is a great asset on and around tricky greens. | F7: Wyndham Clark | G7: Pre | H7: E/W | I7: 28-1 | J7: 1/5 Top 8 | K7: 15 | L7: Bet365 | M7: Pending | N7: Pending | O7: 0 | P7: =SUM(O7-K7) -> -15 | Q7: Pending | R7: Pending | S7: Pending | T7: Pending
A8: 06/07/2026 | B8: DP World Tour | C8: Genesis Scottish Open | D8: The Renaissance Club | E8: Course The Renaissance Club, North Berwick, East Lothian, Scotland Length 7,282 yards Par 70 Course make-up Three par-fives; ten par-fours; five par-threes Course type Links Grass type Greens are fescue-based, similar to those used at Castle Stuart in this event in the relatively recent past, as well as at Royal Birkdale for the 2017 Open Championship. Course overview The Renaissance Club, which opened in 2008, was designed by Tom Doak. It made its Scottish Open debut in 2019, hosting every year since. Three holes run directly along the Firth of Forth, but this is not a pure links test, with some trees in strategic fairway and greenside positions. Heavily contoured greens are the main defence of the course What will it take to win? A strong short-game is a great asset on and around tricky greens. | F8: Bernd Wiesberger | G8: Pre | H8: E/W | I8: 150-1 | J8: 1/5 Top 10 | K8: 3.5 | L8: Bet365 | M8: Pending | N8: Pending | O8: 0 | P8: =SUM(O8-K8) -> -3.5 | Q8: Pending | R8: Pending | S8: Pending | T8: Pending
A9: 06/07/2026 | B9: DP World Tour | C9: Genesis Scottish Open | D9: The Renaissance Club | E9: Course The Renaissance Club, North Berwick, East Lothian, Scotland Length 7,282 yards Par 70 Course make-up Three par-fives; ten par-fours; five par-threes Course type Links Grass type Greens are fescue-based, similar to those used at Castle Stuart in this event in the relatively recent past, as well as at Royal Birkdale for the 2017 Open Championship. Course overview The Renaissance Club, which opened in 2008, was designed by Tom Doak. It made its Scottish Open debut in 2019, hosting every year since. Three holes run directly along the Firth of Forth, but this is not a pure links test, with some trees in strategic fairway and greenside positions. Heavily contoured greens are the main defence of the course What will it take to win? A strong short-game is a great asset on and around tricky greens. | F9: Victor Perez | G9: Pre | H9: E/W | I9: 130-1 | J9: 1/5 Top 10 | K9: 3.5 | L9: Coral | M9: Pending | N9: Pending | O9: 0 | P9: =SUM(O9-K9) -> -3.5 | Q9: Pending | R9: Pending | S9: Pending | T9: Pending
A10: 06/07/2026 | B10: DP World Tour | C10: Genesis Scottish Open | D10: The Renaissance Club | E10: Course The Renaissance Club, North Berwick, East Lothian, Scotland Length 7,282 yards Par 70 Course make-up Three par-fives; ten par-fours; five par-threes Course type Links Grass type Greens are fescue-based, similar to those used at Castle Stuart in this event in the relatively recent past, as well as at Royal Birkdale for the 2017 Open Championship. Course overview The Renaissance Club, which opened in 2008, was designed by Tom Doak. It made its Scottish Open debut in 2019, hosting every year since. Three holes run directly along the Firth of Forth, but this is not a pure links test, with some trees in strategic fairway and greenside positions. Heavily contoured greens are the main defence of the course What will it take to win? A strong short-game is a great asset on and around tricky greens. | F10: Matt Fitzpatrick | G10: Pre | H10: E/W | I10: 18-1 | J10: 1/5 Top 10 | K10: 20 | L10: Coral | M10: Pending | N10: Pending | O10: 0 | P10: =SUM(O10-K10) -> -20 | Q10: Pending | R10: Pending | S10: Pending | T10: Pending
A11: 06/07/2026 | B11: DP World Tour | C11: Genesis Scottish Open | D11: The Renaissance Club | E11: Course The Renaissance Club, North Berwick, East Lothian, Scotland Length 7,282 yards Par 70 Course make-up Three par-fives; ten par-fours; five par-threes Course type Links Grass type Greens are fescue-based, similar to those used at Castle Stuart in this event in the relatively recent past, as well as at Royal Birkdale for the 2017 Open Championship. Course overview The Renaissance Club, which opened in 2008, was designed by Tom Doak. It made its Scottish Open debut in 2019, hosting every year since. Three holes run directly along the Firth of Forth, but this is not a pure links test, with some trees in strategic fairway and greenside positions. Heavily contoured greens are the main defence of the course What will it take to win? A strong short-game is a great asset on and around tricky greens. | F11: Marco Penge | G11: Pre | H11: E/W | I11: 70-1 | J11: 1/5 Top 8 | K11: 7.5 | L11: Bet365 | M11: Pending | N11: Pending | O11: 0 | P11: =SUM(O11-K11) -> -7.5 | Q11: Pending | R11: Pending | S11: Pending | T11: Pending
A12: 01/07/2026 | B12: DP World Tour | C12: BMW International Open | D12: Golfclub Munchen Eichenried | E12: Course Golfclub Munchen Eichenried, Munich, Germany Length 7,347 yards Par 72 four par-fives; ten par-fours; four par-threes Course Make Up four par-fives; ten par-fours; four par-threes Course Type Parkland Grass Type Greens are Creeping Bentgrass Course Overview Eichenried has hosted this event 28 times, most recently from 1997 to 2011, then 2013, 2015, 2017 and from 2019 onwards. The flat, straightforward layout, with four par-fives reachable in two shots, has staged 11 rounds of 62. What will it take to win? History has proven that many types of players with different styles have succeeded here – it could be either a high GIR player who putts well, or someone in good putting. Form who finds more greens than normal who prevails. Either way, birdies and low scoring are the order of the day, particularly if rain does soften up the putting surfaces before the event as is forecast. | F12: Kazuma Kobori | G12: Pre | H12: First Round Leader E/W | I12: 70-1 | J12: 1/4 Top 5 | K12: 2.5 | L12: Coral | M12: N/A | N12: Loss | O12: 0 | P12: =SUM(O12-K12) -> -2.5 | Q12: Michael Hollick | R12: N/A | S12: Pending | T12: Pending
A13: 01/07/2026 | B13: DP World Tour | C13: BMW International Open | D13: Golfclub Munchen Eichenried | E13: Course Golfclub Munchen Eichenried, Munich, Germany Length 7,347 yards Par 72 four par-fives; ten par-fours; four par-threes Course Make Up four par-fives; ten par-fours; four par-threes Course Type Parkland Grass Type Greens are Creeping Bentgrass Course Overview Eichenried has hosted this event 28 times, most recently from 1997 to 2011, then 2013, 2015, 2017 and from 2019 onwards. The flat, straightforward layout, with four par-fives reachable in two shots, has staged 11 rounds of 62. What will it take to win? History has proven that many types of players with different styles have succeeded here – it could be either a high GIR player who putts well, or someone in good putting. Form who finds more greens than normal who prevails. Either way, birdies and low scoring are the order of the day, particularly if rain does soften up the putting surfaces before the event as is forecast. | F13: Calum Hill | G13: Pre | H13: First Round Leader E/W | I13: 66-1 | J13: 1/4 Top 5 | K13: 2.5 | L13: Coral | M13: N/A | N13: Loss | O13: 0 | P13: =SUM(O13-K13) -> -2.5 | Q13: Michael Hollick | R13: N/A | S13: Pending | T13: Pending
A14: 46204 | B14: PGA Tour | C14: John Deere Classic | D14: TPC Deere Run | E14: Course TPC Deere Run, Silvis, Illinois Length 7,327 yards Par 71 Course make-up Three par-fives; 11 par-fours; four par-threes Course type Parkland Grass type Fairways: Southshore Bentgrass; Rough: Kentucky Bluegrass with Fine Fescue 4″; Greens: 5,500 sq.ft average featuring L-93 Bentgrass; Stimpmeter: 11ft. Course overview The John Deere Classic has been held at TPC Deere Run since 2000. The track, crafted by DA Weibring in 1999, is one of the easiest the Tour stars face all season. The first and second holes are extremely simple, so there is scope for a fast start, and this is a birdiefest where only the hottest of putters will contend. What will it take to win? Steve Stricker, awesome with wedge in hand and one of the best putters in the world, won this event three times in a row before Zach Johnson, a player of a similar ilk, ended that streak. The John Deere lends itself to low scoring, with wedges and putter the key clubs in the bag | F14: Eric Cole | G14: Pre | H14: First Round Leader E/W | I14: 45-1 | J14: 1/5 Top 7 | K14: 2.5 | L14: Coral | M14: N/A | N14: Loss | O14: 0 | P14: =SUM(O14-K14) -> -2.5 | Q14: Chris Gotterup | R14: 16-1 | S14: Pending | T14: Pending
A15: 46204 | B15: PGA Tour | C15: John Deere Classic | D15: TPC Deere Run | E15: Course TPC Deere Run, Silvis, Illinois Length 7,327 yards Par 71 Course make-up Three par-fives; 11 par-fours; four par-threes Course type Parkland Grass type Fairways: Southshore Bentgrass; Rough: Kentucky Bluegrass with Fine Fescue 4″; Greens: 5,500 sq.ft average featuring L-93 Bentgrass; Stimpmeter: 11ft. Course overview The John Deere Classic has been held at TPC Deere Run since 2000. The track, crafted by DA Weibring in 1999, is one of the easiest the Tour stars face all season. The first and second holes are extremely simple, so there is scope for a fast start, and this is a birdiefest where only the hottest of putters will contend. What will it take to win? Steve Stricker, awesome with wedge in hand and one of the best putters in the world, won this event three times in a row before Zach Johnson, a player of a similar ilk, ended that streak. The John Deere lends itself to low scoring, with wedges and putter the key clubs in the bag | F15: Aldrich Potgieter | G15: Pre | H15: First Round Leader E/W | I15: 75-1 | J15: 1/5 Top 7 | K15: 2.5 | L15: Coral | M15: N/A | N15: Loss | O15: 0 | P15: =SUM(O15-K15) -> -2.5 | Q15: Chris Gotterup | R15: 16-1 | S15: Pending | T15: Pending
A16: 30/06/2026 | B16: DP World Tour | C16: BMW International Open | D16: Golfclub Munchen Eichenried | E16: Course Golfclub Munchen Eichenried, Munich, Germany Length 7,347 yards Par 72 four par-fives; ten par-fours; four par-threes Course Make Up four par-fives; ten par-fours; four par-threes Course Type Parkland Grass Type Greens are Creeping Bentgrass Course Overview Eichenried has hosted this event 28 times, most recently from 1997 to 2011, then 2013, 2015, 2017 and from 2019 onwards. The flat, straightforward layout, with four par-fives reachable in two shots, has staged 11 rounds of 62. What will it take to win? History has proven that many types of players with different styles have succeeded here – it could be either a high GIR player who putts well, or someone in good putting. Form who finds more greens than normal who prevails. Either way, birdies and low scoring are the order of the day, particularly if rain does soften up the putting surfaces before the event as is forecast. | F16: Oihan Guillamoundeguy | G16: Pre | H16: E/W | I16: 125-1 | J16: 1/5 Top 8 | K16: 2.5 | L16: Bet365 | M16: T4 | N16: Place | O16: 32.5 | P16: =SUM(O16-K16) -> 30 | Q16: Michael Hollick | R16: N/A | S16: Pending | T16: Pending
A17: 46203 | B17: DP World Tour | C17: BMW International Open | D17: Golfclub Munchen Eichenried | E17: Course Golfclub Munchen Eichenried, Munich, Germany Length 7,347 yards Par 72 four par-fives; ten par-fours; four par-threes Course Make Up four par-fives; ten par-fours; four par-threes Course Type Parkland Grass Type Greens are Creeping Bentgrass Course Overview Eichenried has hosted this event 28 times, most recently from 1997 to 2011, then 2013, 2015, 2017 and from 2019 onwards. The flat, straightforward layout, with four par-fives reachable in two shots, has staged 11 rounds of 62. What will it take to win? History has proven that many types of players with different styles have succeeded here – it could be either a high GIR player who putts well, or someone in good putting. Form who finds more greens than normal who prevails. Either way, birdies and low scoring are the order of the day, particularly if rain does soften up the putting surfaces before the event as is forecast. | F17: Marcus Armitage | G17: Pre | H17: E/W | I17: 66-1 | J17: 1/5 Top 8 | K17: 5 | L17: Bet365 | M17: T50 | N17: Loss | O17: 0 | P17: =SUM(O17-K17) -> -5 | Q17: Michael Hollick | R17: N/A | S17: Pending | T17: Pending
A18: 46203 | B18: Multiple | C18: John Deere Classic / BMW International Open | D18: N/A | E18: N/A | F18: Joaquin Niemann / Jackson Koivun | G18: Pre | H18: E/W Double | I18: 201-1 | J18: 1/4 Top 5 | K18: 5 | L18: Bet365 | M18: N/A | N18: Loss | O18: 0 | P18: =SUM(O18-K18) -> -5 | Q18: N/A | R18: N/A | S18: Pending | T18: Pending
A19: 46202 | B19: DP World Tour | C19: BMW International Open | D19: Golfclub Munchen Eichenried | E19: Course Golfclub Munchen Eichenried, Munich, Germany Length 7,347 yards Par 72 four par-fives; ten par-fours; four par-threes Course Make Up four par-fives; ten par-fours; four par-threes Course Type Parkland Grass Type Greens are Creeping Bentgrass Course Overview Eichenried has hosted this event 28 times, most recently from 1997 to 2011, then 2013, 2015, 2017 and from 2019 onwards. The flat, straightforward layout, with four par-fives reachable in two shots, has staged 11 rounds of 62. What will it take to win? History has proven that many types of players with different styles have succeeded here – it could be either a high GIR player who putts well, or someone in good putting. Form who finds more greens than normal who prevails. Either way, birdies and low scoring are the order of the day, particularly if rain does soften up the putting surfaces before the event as is forecast. | F19: Kazuma Kobori | G19: Pre | H19: E/W | I19: 55-1 | J19: 1/5 Top 8 | K19: 7.5 | L19: Betfred | M19: CUT | N19: Loss | O19: 0 | P19: =SUM(O19-K19) -> -7.5 | Q19: Michael Hollick | R19: N/A | S19: Pending | T19: Pending
A20: 46202 | B20: PGA Tour | C20: John Deere Classic | D20: TPC Deere Run | E20: Course TPC Deere Run, Silvis, Illinois Length 7,327 yards Par 71 Course make-up Three par-fives; 11 par-fours; four par-threes Course type Parkland Grass type Fairways: Southshore Bentgrass; Rough: Kentucky Bluegrass with Fine Fescue 4″; Greens: 5,500 sq.ft average featuring L-93 Bentgrass; Stimpmeter: 11ft. Course overview The John Deere Classic has been held at TPC Deere Run since 2000. The track, crafted by DA Weibring in 1999, is one of the easiest the Tour stars face all season. The first and second holes are extremely simple, so there is scope for a fast start, and this is a birdiefest where only the hottest of putters will contend. What will it take to win? Steve Stricker, awesome with wedge in hand and one of the best putters in the world, won this event three times in a row before Zach Johnson, a player of a similar ilk, ended that streak. The John Deere lends itself to low scoring, with wedges and putter the key clubs in the bag | F20: Aldrich Potgieter | G20: Pre | H20: E/W | I20: 45-1 | J20: 1/5 Top 8 | K20: 10 | L20: Coral | M20: CUT | N20: Loss | O20: 0 | P20: =SUM(O20-K20) -> -10 | Q20: Chris Gotterup | R20: 16-1 | S20: Pending | T20: Pending
A21: 46202 | B21: PGA Tour | C21: John Deere Classic | D21: TPC Deere Run | E21: Course TPC Deere Run, Silvis, Illinois Length 7,327 yards Par 71 Course make-up Three par-fives; 11 par-fours; four par-threes Course type Parkland Grass type Fairways: Southshore Bentgrass; Rough: Kentucky Bluegrass with Fine Fescue 4″; Greens: 5,500 sq.ft average featuring L-93 Bentgrass; Stimpmeter: 11ft. Course overview The John Deere Classic has been held at TPC Deere Run since 2000. The track, crafted by DA Weibring in 1999, is one of the easiest the Tour stars face all season. The first and second holes are extremely simple, so there is scope for a fast start, and this is a birdiefest where only the hottest of putters will contend. What will it take to win? Steve Stricker, awesome with wedge in hand and one of the best putters in the world, won this event three times in a row before Zach Johnson, a player of a similar ilk, ended that streak. The John Deere lends itself to low scoring, with wedges and putter the key clubs in the bag | F21: Jackson Koivun | G21: Pre | H21: E/W | I21: 20-1 | J21: 1/5 Top 10 | K21: 20 | L21: Coral | M21: CUT | N21: Loss | O21: 0 | P21: =SUM(O21-K21) -> -20 | Q21: Chris Gotterup | R21: 16-1 | S21: Pending | T21: Pending
A22: 46202 | B22: PGA Tour | C22: Travellers Championship | D22: TPC River Highlands | E22: Course TPC River Highlands, Cromwell, Connecticut Length 6,844 yards Par 70 Course make-up Two par-fives; 12 par-fours; four par-threes Course type Parkland Grass type Fairways: Bentgrass with Poa Annua; Rough: Kentucky Bluegrass with Fescue +4″; Greens: 5,000 sq.ft average featuring Bentgrass with Poa Annua; Tournament Stimp: 11ft. Course overview This Pete Dye creation has hosted this event since 1984, but it was redesigned in 1989, its name changing from TPC Connecticut to TPC River Highlands. Only the Phoenix Open attracts more spectators to a PGA Tour event than the Travelers What will it take to win? All types of player have succeeded at this venue – short-hitters like Olin Browne, Woody Austin, Ken Duke, Kevin Streelman, Russell Knox and Chez Reavie have won on the same terrain as bombers like Phil Mickelson, Bubba Watson and Dustin Johnson. Hitting plenty of greens and putting well is the route to success. Birdies aplenty are up for grabs, so weak putters will be left behind. | F22: Ryan Fox | G22: Pre | H22: First Round Leader E/W | I22: 70-1 | J22: 1/4 Top 5 | K22: 2.5 | L22: SkyBet | M22: N/A | N22: Loss | O22: 0 | P22: =SUM(O22-K22) -> -2.5 | Q22: Viktor Hovland | R22: 40-1 | S22: Pending | T22: Pending
A23: 46198 | B23: PGA Tour | C23: Travellers Championship | D23: TPC River Highlands | E23: Course TPC River Highlands, Cromwell, Connecticut Length 6,844 yards Par 70 Course make-up Two par-fives; 12 par-fours; four par-threes Course type Parkland Grass type Fairways: Bentgrass with Poa Annua; Rough: Kentucky Bluegrass with Fescue +4″; Greens: 5,000 sq.ft average featuring Bentgrass with Poa Annua; Tournament Stimp: 11ft. Course overview This Pete Dye creation has hosted this event since 1984, but it was redesigned in 1989, its name changing from TPC Connecticut to TPC River Highlands. Only the Phoenix Open attracts more spectators to a PGA Tour event than the Travelers What will it take to win? All types of player have succeeded at this venue – short-hitters like Olin Browne, Woody Austin, Ken Duke, Kevin Streelman, Russell Knox and Chez Reavie have won on the same terrain as bombers like Phil Mickelson, Bubba Watson and Dustin Johnson. Hitting plenty of greens and putting well is the route to success. Birdies aplenty are up for grabs, so weak putters will be left behind. | F23: Tom Hoge | G23: Pre | H23: First Round Leader E/W | I23: 125-1 | J23: 1/4 Top 5 | K23: 2.5 | L23: SkyBet | M23: N/A | N23: Loss | O23: 0 | P23: =SUM(O23-K23) -> -2.5 | Q23: Viktor Hovland | R23: 40-1 | S23: Pending | T23: Pending
A24: 46198 | B24: PGA Tour | C24: Travellers Championship | D24: TPC River Highlands | E24: Course TPC River Highlands, Cromwell, Connecticut Length 6,844 yards Par 70 Course make-up Two par-fives; 12 par-fours; four par-threes Course type Parkland Grass type Fairways: Bentgrass with Poa Annua; Rough: Kentucky Bluegrass with Fescue +4″; Greens: 5,000 sq.ft average featuring Bentgrass with Poa Annua; Tournament Stimp: 11ft. Course overview This Pete Dye creation has hosted this event since 1984, but it was redesigned in 1989, its name changing from TPC Connecticut to TPC River Highlands. Only the Phoenix Open attracts more spectators to a PGA Tour event than the Travelers What will it take to win? All types of player have succeeded at this venue – short-hitters like Olin Browne, Woody Austin, Ken Duke, Kevin Streelman, Russell Knox and Chez Reavie have won on the same terrain as bombers like Phil Mickelson, Bubba Watson and Dustin Johnson. Hitting plenty of greens and putting well is the route to success. Birdies aplenty are up for grabs, so weak putters will be left behind. | F24: Jackson Suber | G24: Pre | H24: First Round Leader E/W | I24: 90-1 | J24: 1/4 Top 5 | K24: 2.5 | L24: SkyBet | M24: N/A | N24: Loss | O24: 0 | P24: =SUM(O24-K24) -> -2.5 | Q24: Viktor Hovland | R24: 40-1 | S24: Pending | T24: Pending
A25: 46198 | B25: PGA Tour | C25: Travellers Championship | D25: TPC River Highlands | E25: Course TPC River Highlands, Cromwell, Connecticut Length 6,844 yards Par 70 Course make-up Two par-fives; 12 par-fours; four par-threes Course type Parkland Grass type Fairways: Bentgrass with Poa Annua; Rough: Kentucky Bluegrass with Fescue +4″; Greens: 5,000 sq.ft average featuring Bentgrass with Poa Annua; Tournament Stimp: 11ft. Course overview This Pete Dye creation has hosted this event since 1984, but it was redesigned in 1989, its name changing from TPC Connecticut to TPC River Highlands. Only the Phoenix Open attracts more spectators to a PGA Tour event than the Travelers What will it take to win? All types of player have succeeded at this venue – short-hitters like Olin Browne, Woody Austin, Ken Duke, Kevin Streelman, Russell Knox and Chez Reavie have won on the same terrain as bombers like Phil Mickelson, Bubba Watson and Dustin Johnson. Hitting plenty of greens and putting well is the route to success. Birdies aplenty are up for grabs, so weak putters will be left behind. | F25: Ben James | G25: Pre | H25: First Round Leader E/W | I25: 60-1 | J25: 1/4 Top 5 | K25: 0 | L25: SkyBet | M25: N/A | N25: Loss | O25: 0 | P25: =SUM(O25-K25) -> 0 | Q25: Viktor Hovland | R25: 40-1 | S25: Pending | T25: Pending
A26: 46198 | B26: PGA Tour | C26: Travellers Championship | D26: TPC River Highlands | E26: Course TPC River Highlands, Cromwell, Connecticut Length 6,844 yards Par 70 Course make-up Two par-fives; 12 par-fours; four par-threes Course type Parkland Grass type Fairways: Bentgrass with Poa Annua; Rough: Kentucky Bluegrass with Fescue +4″; Greens: 5,000 sq.ft average featuring Bentgrass with Poa Annua; Tournament Stimp: 11ft. Course overview This Pete Dye creation has hosted this event since 1984, but it was redesigned in 1989, its name changing from TPC Connecticut to TPC River Highlands. Only the Phoenix Open attracts more spectators to a PGA Tour event than the Travelers What will it take to win? All types of player have succeeded at this venue – short-hitters like Olin Browne, Woody Austin, Ken Duke, Kevin Streelman, Russell Knox and Chez Reavie have won on the same terrain as bombers like Phil Mickelson, Bubba Watson and Dustin Johnson. Hitting plenty of greens and putting well is the route to success. Birdies aplenty are up for grabs, so weak putters will be left behind. | F26: Eric Cole | G26: Pre | H26: First Round Leader E/W | I26: 50-1 | J26: 1/4 Top 5 | K26: 0 | L26: SkyBet | M26: 1 | N26: win | O26: 78.13 | P26: =SUM(O26-K26) -> 78.13 | Q26: Viktor Hovland | R26: 40-1 | S26: Pending | T26: Pending
A27: 46198 | B27: DP World Tour | C27: Italian Open | D27: Circolo Golf Torino | E27: Course The Blue Course at Circolo Golf Torino, Fiano, Italy Length 7,214 yards Par 71 Course make-up three par-fives; 12 par-fours; four par-threes Course type Parkland Grass type The course features Bentgrass greens and Bent/Poa grass fairways Course overview Set within the former royal hunting grounds of La Mandria near Turin, the fairways are framed by mature oak, chestnut and birch trees, creating tight driving corridors that place a greater emphasis on positioning than power. Designed by John Morrison and later refined by Michael Hurdzan and Dana Fry, this parkland course isn’t overly long by modern standards, placing a premium on strategy, accuracy and precise iron play. Three reachable par 5s offer the majority of the scoring opportunities, while a series of lengthy par 4s — most notably the 514-yard 12th — ensure players must combine strong driving with high-quality long-iron play. Bentgrass greens, narrow fairways and mature woodland create one of the most strategic tests on the DP World Tour schedule, favouring complete ball-strikers over outright power specialists. What will it take to win? Players who excel in finding fairways and consistently hitting greens in regulation are likely to enjoy a significant advantage over the week’s more aggressive bombers. | F27: Maximilian Steinlechner | G27: Pre | H27: First Round Leader E/W | I27: 100-1 | J27: 1/4 Top 5 | K27: 2.5 | L27: Coral | M27: N/A | N27: Loss | O27: 0 | P27: =SUM(O27-K27) -> -2.5 | Q27: Eugenio Chacarra | R27: 20-1 | S27: Pending | T27: Pending
A28: 46197 | B28: DP World Tour | C28: Italian Open | D28: Circolo Golf Torino | E28: Course The Blue Course at Circolo Golf Torino, Fiano, Italy Length 7,214 yards Par 71 Course make-up three par-fives; 12 par-fours; four par-threes Course type Parkland Grass type The course features Bentgrass greens and Bent/Poa grass fairways Course overview Set within the former royal hunting grounds of La Mandria near Turin, the fairways are framed by mature oak, chestnut and birch trees, creating tight driving corridors that place a greater emphasis on positioning than power. Designed by John Morrison and later refined by Michael Hurdzan and Dana Fry, this parkland course isn’t overly long by modern standards, placing a premium on strategy, accuracy and precise iron play. Three reachable par 5s offer the majority of the scoring opportunities, while a series of lengthy par 4s — most notably the 514-yard 12th — ensure players must combine strong driving with high-quality long-iron play. Bentgrass greens, narrow fairways and mature woodland create one of the most strategic tests on the DP World Tour schedule, favouring complete ball-strikers over outright power specialists. What will it take to win? Players who excel in finding fairways and consistently hitting greens in regulation are likely to enjoy a significant advantage over the week’s more aggressive bombers. | F28: Calum Hill | G28: Pre | H28: First Round Leader E/W | I28: 66-1 | J28: 1/4 Top 5 | K28: 2.5 | L28: Coral | M28: N/A | N28: Loss | O28: 0 | P28: =SUM(O28-K28) -> -2.5 | Q28: Eugenio Chacarra | R28: 20-1 | S28: Pending | T28: Pending
... A103: 46148 | B103: PGA Tour | C103: Truist Championship | D103: Quail Hollow Club | E103: Course Quail Hollow Club, Charlotte, North Carolina Length 7,583 yards Par 71 Course make up Three par-fives; 11 par-fours; four par-threes Course type Parkland Grass Type Fairways: 419 Bermudagrass overseeded with Perennial Ryegrass; Rough: 419 Bermudagrass overseeded with Perennial Ryegrass 2”; Greens: 6,578 sq.ft average featuring G12 Champion Bermudagrass overseeded with Poa Trivialis; Target Tournament Stimp: 12ft. Course overview Quail Hollow has hosted a regulation PGA Tour event every year since 2003 (Wachovia Championship, Quail Hollow Championship, Wells Fargo Championship), apart from 2017, 2020 (Covid), 2022 and last year. In 2017 and last year, the US PGA Championship was at Quail Hollow, then in 2022 the Presidents Cup was staged there. The course has been redesigned through the years. A renovation prior to the 2024 Wells Fargo switched the fairways to a new custom perennial ryegrass blend and the greens to TifEagle Bermuda, so form from the 2024 Wells Fargo and the 2025 US PGA is of most value to punters. What will it take to win the Truist? As with last week's Signature Event at Doral, another test of driving awaits. Long, straight hitting off the tee is the key to success at Quail Hollow. | F103: Xander Schauffele | G103: Pre | H103: Outright | I103: 12-1 | J103: N/A | K103: 10 | L103: SkyBet | M103: T60 | N103: Loss | O103: 0 | P103: =SUM(O103-K103) -> -10 | Q103: Kristopher Reitan | R103: 80-1 | S103: Pending | T103: Pending
A104: 46147 | B104: DP World Tour | C104: Estrella Damm Catalunya Championship | D104: Real Club de Golf El Prat | F104: Darius Van Driel | G104: Pre | H104: E/W | I104: 50-1 | J104: 1/5 Top 8 | K104: 7.5 | L104: Betfred | M104: CUT | N104: Loss | O104: 0 | P104: =SUM(O104-K104) -> -7.5 | Q104: Yurav Premlall | R104: N/A | S104: Pending | T104: Pending
A105: 46146 | B105: PGA Tour | C105: Myrtle Beach Classic | D105: The Dunes Golf and Beach Club | E105: Course The Dunes Golf and Beach Club, Myrtle Beach, South Carolina Length 7,347 yards Par 71 – three par-fives; 11 par-fours; four par-threes Time difference South Carolina is five hours behind the UK and Ireland Course type Parkland Grass Type Fairways: Ryegrass overseed; Rough: Bermudagrass overseeded with Perennial Ryegrass 2.5″; Greens: 6,000 sq.ft average featuring Champion UltraDwarf Bermudagrass. Course overview The largely tree-lined Robert Jones Senior designed Dunes Club made its PGA Tour debut last year. It runs alongside Lake Singleton and water comes into play on most holes. The average winning total in the six editions of the Champions Tour event staged there (Senior Tour Championship, 1994 through 1999) was 12 under par, but Chris Gotterup romped to 22 under par 12 months ago Type of player suited to the challenge Generous fairways and wide greens should result in low scoring, so expect an attacking powerhouse to prevail, as was the case last year Key attribute Power | F105: Steven Fisk | G105: Pre | H105: E/W | I105: 35-1 | J105: 1/5 Top 8 | K105: 10 | L105: Bet365 | M105: T38 | N105: Loss | O105: 0 | P105: =SUM(O105-K105) -> -10 | Q105: Brandt Snedeker | R105: 175-1 | S105: Pending | T105: Pending
A106: 46146 | B106: PGA Tour | C106: Truist Championship | D106: Quail Hollow Club | E106: Course Quail Hollow Club, Charlotte, North Carolina Length 7,583 yards Par 71 Course make up Three par-fives; 11 par-fours; four par-threes Course type Parkland Grass Type Fairways: 419 Bermudagrass overseeded with Perennial Ryegrass; Rough: 419 Bermudagrass overseeded with Perennial Ryegrass 2”; Greens: 6,578 sq.ft average featuring G12 Champion Bermudagrass overseeded with Poa Trivialis; Target Tournament Stimp: 12ft. Course overview Quail Hollow has hosted a regulation PGA Tour event every year since 2003 (Wachovia Championship, Quail Hollow Championship, Wells Fargo Championship), apart from 2017, 2020 (Covid), 2022 and last year. In 2017 and last year, the US PGA Championship was at Quail Hollow, then in 2022 the Presidents Cup was staged there. The course has been redesigned through the years. A renovation prior to the 2024 Wells Fargo switched the fairways to a new custom perennial ryegrass blend and the greens to TifEagle Bermuda, so form from the 2024 Wells Fargo and the 2025 US PGA is of most value to punters. What will it take to win the Truist? As with last week's Signature Event at Doral, another test of driving awaits. Long, straight hitting off the tee is the key to success at Quail Hollow. | F106: Aldrich Potgieter | G106: Pre | H106: E/W | I106: 140-1 | J106: 1/5 Top 8 | K106: 2.5 | L106: Coral | M106: T48 | N106: Loss | O106: 0 | P106: =SUM(O106-K106) -> -2.5 | Q106: Kristopher Reitan | R106: 80-1 | S106: Pending | T106: Pending
A107: 46146 | B107: PGA Tour | C107: Truist Championship | D107: Quail Hollow Club | E107: Course Quail Hollow Club, Charlotte, North Carolina Length 7,583 yards Par 71 Course make up Three par-fives; 11 par-fours; four par-threes Course type Parkland Grass Type Fairways: 419 Bermudagrass overseeded with Perennial Ryegrass; Rough: 419 Bermudagrass overseeded with Perennial Ryegrass 2”; Greens: 6,578 sq.ft average featuring G12 Champion Bermudagrass overseeded with Poa Trivialis; Target Tournament Stimp: 12ft. Course overview Quail Hollow has hosted a regulation PGA Tour event every year since 2003 (Wachovia Championship, Quail Hollow Championship, Wells Fargo Championship), apart from 2017, 2020 (Covid), 2022 and last year. In 2017 and last year, the US PGA Championship was at Quail Hollow, then in 2022 the Presidents Cup was staged there. The course has been redesigned through the years. A renovation prior to the 2024 Wells Fargo switched the fairways to a new custom perennial ryegrass blend and the greens to TifEagle Bermuda, so form from the 2024 Wells Fargo and the 2025 US PGA is of most value to punters. What will it take to win the Truist? As with last week's Signature Event at Doral, another test of driving awaits. Long, straight hitting off the tee is the key to success at Quail Hollow. | F107: Sahith Theegala | G107: Pre | H107: E/W | I107: 80-1 | J107: 1/5 Top 8 | K107: 5 | L107: Coral | M107: 69 | N107: Loss | O107: 0 | P107: =SUM(O107-K107) -> -5 | Q107: Kristopher Reitan | R107: 80-1 | S107: Pending | T107: Pending
A108: 46146 | B108: PGA Tour | C108: Truist Championship | D108: Quail Hollow Club | E108: Course Quail Hollow Club, Charlotte, North Carolina Length 7,583 yards Par 71 Course make up Three par-fives; 11 par-fours; four par-threes Course type Parkland Grass Type Fairways: 419 Bermudagrass overseeded with Perennial Ryegrass; Rough: 419 Bermudagrass overseeded with Perennial Ryegrass 2”; Greens: 6,578 sq.ft average featuring G12 Champion Bermudagrass overseeded with Poa Trivialis; Target Tournament Stimp: 12ft. Course overview Quail Hollow has hosted a regulation PGA Tour event every year since 2003 (Wachovia Championship, Quail Hollow Championship, Wells Fargo Championship), apart from 2017, 2020 (Covid), 2022 and last year. In 2017 and last year, the US PGA Championship was at Quail Hollow, then in 2022 the Presidents Cup was staged there. The course has been redesigned through the years. A renovation prior to the 2024 Wells Fargo switched the fairways to a new custom perennial ryegrass blend and the greens to TifEagle Bermuda, so form from the 2024 Wells Fargo and the 2025 US PGA is of most value to punters. What will it take to win the Truist? As with last week's Signature Event at Doral, another test of driving awaits. Long, straight hitting off the tee is the key to success at Quail Hollow. | F108: Ben Griffin | G108: Pre | H108: E/W | I108: 35-1 | J108: 1/5 Top 8 | K108: 10 | L108: Coral | M108: T63 | N108: Loss | O108: 0 | P108: =SUM(O108-K108) -> -10 | Q108: Kristopher Reitan | R108: 80-1 | S108: Pending | T108: Pending
A109: 46146 | B109: DP World Tour | C109: Turkish Airlines Open | D109: Trump National Doral | E109: Course Blue Monster Course, Trump National Doral, Miami, Florida Length 7,739 yards Par 72 Course make up Four par-fives; ten par-fours; four par-threes Course type Parkland Grass type Fairways: Bermudagrass; Rough: Bermudagrass 3″; Greens: TifEagle Bermudagrass; Tournament Stimp: 11-11.5 ft. Course Overview The Blue Monster hosted the Doral Open/Ford Championship/CA Championship on the PGA Tour from 1962 to 2006. From 2007 through 2016, it hosted the WGC-Cadillac Championship. Gil Hanse redesigned the Blue Monster before the 2014 Cadillac. Dick Wilson's famous track had been getting too easy, the ancient layout providing something far from monstrous for professionals with modern equipment in their hands, underlined by a 2013 winning score of 19 under par from Tiger Woods. Donald Trump funded a $200m upgrade to bolster Doral and Hanse announced afterwards: “It's pretty much a brand-new golf course.” Every hole was changed and the toughened-up track produced a four-under-par winning total in 2014. Adam Scott won the last WGC-Cadillac with a 12-under-par total. The last two events at this course were the 2024 and 2025 LIV Miami – 54-hole events won by Dean Burmester and Marc Leishman. What will it take to win? Course form prior to 2014 is of limited value. Length off the tee is extremely beneficial on the revised layout. Expect powerhouses to dominate in fine weather. | F109: Bernd Wiesberger | G109: Pre | H109: First Round Leader E/W | I109: 50-1 | J109: 1/4 Top 5 | K109: 2.5 | L109: Bet365 | M109: N/A | N109: Loss | O109: 0 | P109: =SUM(O109-K109) -> -2.5 | Q109: Mikael Lindberg | R109: 40-1 | S109: Pending | T109: Pending
A110: 46141 | B110: DP World Tour | C110: Turkish Airlines Open | D110: Trump National Doral | E110: Course Blue Monster Course, Trump National Doral, Miami, Florida Length 7,739 yards Par 72 Course make up Four par-fives; ten par-fours; four par-threes Course type Parkland Grass type Fairways: Bermudagrass; Rough: Bermudagrass 3″; Greens: TifEagle Bermudagrass; Tournament Stimp: 11-11.5 ft. Course Overview The Blue Monster hosted the Doral Open/Ford Championship/CA Championship on the PGA Tour from 1962 to 2006. From 2007 through 2016, it hosted the WGC-Cadillac Championship. Gil Hanse redesigned the Blue Monster before the 2014 Cadillac. Dick Wilson's famous track had been getting too easy, the ancient layout providing something far from monstrous for professionals with modern equipment in their hands, underlined by a 2013 winning score of 19 under par from Tiger Woods. Donald Trump funded a $200m upgrade to bolster Doral and Hanse announced afterwards: “It's pretty much a brand-new golf course.” Every hole was changed and the toughened-up track produced a four-under-par winning total in 2014. Adam Scott won the last WGC-Cadillac with a 12-under-par total. The last two events at this course were the 2024 and 2025 LIV Miami – 54-hole events won by Dean Burmester and Marc Leishman. What will it take to win? Course form prior to 2014 is of limited value. Length off the tee is extremely beneficial on the revised layout. Expect powerhouses to dominate in fine weather. | F110: Kiradech Aphibarnrat | G110: Pre | H110: First Round Leader E/W | I110: 80-1 | J110: 1/4 Top 5 | K110: 2.5 | L110: Bet365 | M110: N/A | N110: Loss | O110: 0 | P110: =SUM(O110-K110) -> -2.5 | Q110: Mikael Lindberg | R110: 40-1 | S110: Pending | T110: Pending
A111: 46141 | B111: PGA Tour | C111: Cadillac Championship | D111: Trump National Doral | E111: Course Blue Monster Course, Trump National Doral, Miami, Florida Length 7,739 yards Par 72 Course make up Four par-fives; ten par-fours; four par-threes Course type Parkland Grass type Fairways: Bermudagrass; Rough: Bermudagrass 3″; Greens: TifEagle Bermudagrass; Tournament Stimp: 11-11.5 ft. Course Overview The Blue Monster hosted the Doral Open/Ford Championship/CA Championship on the PGA Tour from 1962 to 2006. From 2007 through 2016, it hosted the WGC-Cadillac Championship. Gil Hanse redesigned the Blue Monster before the 2014 Cadillac. Dick Wilson's famous track had been getting too easy, the ancient layout providing something far from monstrous for professionals with modern equipment in their hands, underlined by a 2013 winning score of 19 under par from Tiger Woods. Donald Trump funded a $200m upgrade to bolster Doral and Hanse announced afterwards: “It's pretty much a brand-new golf course.” Every hole was changed and the toughened-up track produced a four-under-par winning total in 2014. Adam Scott won the last WGC-Cadillac with a 12-under-par total. The last two events at this course were the 2024 and 2025 LIV Miami – 54-hole events won by Dean Burmester and Marc Leishman. What will it take to win? Course form prior to 2014 is of limited value. Length off the tee is extremely beneficial on the revised layout. Expect powerhouses to dominate in fine weather. | F111: Pierceson Coody | G111: Pre | H111: First Round Leader E/W | I111: 50-1 | J111: 1/4 Top 5 | K111: 2.5 | L111: Bet365 | M111: N/A | N111: Loss | O111: 0 | P111: =SUM(O111-K111) -> -2.5 | Q111: Cameron Young | R111: 12-1 | S111: Pending | T111: Pending
A112: 46141 | B112: PGA Tour | C112: Cadillac Championship | D112: Trump National Doral | E112: Course Blue Monster Course, Trump National Doral, Miami, Florida Length 7,739 yards Par 72 Course make up Four par-fives; ten par-fours; four par-threes Course type Parkland Grass type Fairways: Bermudagrass; Rough: Bermudagrass 3″; Greens: TifEagle Bermudagrass; Tournament Stimp: 11-11.5 ft. Course Overview The Blue Monster hosted the Doral Open/Ford Championship/CA Championship on the PGA Tour from 1962 to 2006. From 2007 through 2016, it hosted the WGC-Cadillac Championship. Gil Hanse redesigned the Blue Monster before the 2014 Cadillac. Dick Wilson's famous track had been getting too easy, the ancient layout providing something far from monstrous for professionals with modern equipment in their hands, underlined by a 2013 winning score of 19 under par from Tiger Woods. Donald Trump funded a $200m upgrade to bolster Doral and Hanse announced afterwards: “It's pretty much a brand-new golf course.” Every hole was changed and the toughened-up track produced a four-under-par winning total in 2014. Adam Scott won the last WGC-Cadillac with a 12-under-par total. The last two events at this course were the 2024 and 2025 LIV Miami – 54-hole events won by Dean Burmester and Marc Leishman. What will it take to win? Course form prior to 2014 is of limited value. Length off the tee is extremely beneficial on the revised layout. Expect powerhouses to dominate in fine weather. | F112: Jhonattan Vegas | G112: Pre | H112: First Round Leader E/W | I112: 110-1 | J112: 1/4 Top 5 | K112: 2.5 | L112: Bet365 | M112: N/A | N112: Loss | O112: 0 | P112: =SUM(O112-K112) -> -2.5 | Q112: Cameron Young | R112: 12-1 | S112: Pending | T112: Pending
A113: 46141 | B113: Multiple | C113: Cadillac Championship / Turkish Airlines Open | D113: N/A | E113: N/A | F113: Scottie Scheffler / David Puig | G113: Pre | H113: Outright | I113: 43-1 | J113: N/A | K113: 5 | L113: SkyBet | M113: N/A | N113: Loss | O113: 0 | P113: =SUM(O113-K113) -> -5 | Q113: N/A | R113: N/A | S113: Pending | T113: Pending
A114: 46140 | B114: PGA Tour | C114: Cadillac Championship | D114: Trump National Doral | E114: Course Blue Monster Course, Trump National Doral, Miami, Florida Length 7,739 yards Par 72 Course make up Four par-fives; ten par-fours; four par-threes Course type Parkland Grass type Fairways: Bermudagrass; Rough: Bermudagrass 3″; Greens: TifEagle Bermudagrass; Tournament Stimp: 11-11.5 ft. Course Overview The Blue Monster hosted the Doral Open/Ford Championship/CA Championship on the PGA Tour from 1962 to 2006. From 2007 through 2016, it hosted the WGC-Cadillac Championship. Gil Hanse redesigned the Blue Monster before the 2014 Cadillac. Dick Wilson's famous track had been getting too easy, the ancient layout providing something far from monstrous for professionals with modern equipment in their hands, underlined by a 2013 winning score of 19 under par from Tiger Woods. Donald Trump funded a $200m upgrade to bolster Doral and Hanse announced afterwards: “It's pretty much a brand-new golf course.” Every hole was changed and the toughened-up track produced a four-under-par winning total in 2014. Adam Scott won the last WGC-Cadillac with a 12-under-par total. The last two events at this course were the 2024 and 2025 LIV Miami – 54-hole events won by Dean Burmester and Marc Leishman. What will it take to win? Course form prior to 2014 is of limited value. Length off the tee is extremely beneficial on the revised layout. Expect powerhouses to dominate in fine weather. | F114: Chris Gotterup | G114: Pre | H114: E/W | I114: 22-1 | J114: 1/5 Top 8 | K114: 15 | L114: Coral | M114: T38 | N114: Loss | O114: 0 | P114: =SUM(O114-K114) -> -15 | Q114: Cameron Young | R114: 12-1 | S114: Pending | T114: Pending
...

Sheet 2026
A1: Golf Betting Record - 2025
A2: Tour/Majors | B2: DP World Tour | C2: LIV | D2: Majors | E2: Multiple | F2: Olympics | G2: PGA Tour | H2: Ryder Cup | I2: Grand Total
A3: Date (YM) | E3: Profit/Loss (Sum)
A4: 45078 | D4: 0 | I4: 0
A5: 45108 | D5: 0 | E5: 0 | I5: 0
A6: 45170 | B6: 0 | C6: 0 | H6: 0 | I6: 0
A7: 45200 | B7: 0 | E7: 0 | I7: 0
A8: 45352 | E8: 0 | G8: 0 | I8: 0
A9: 45383 | B9: 0 | C9: 0 | D9: 0 | E9: 0 | G9: 0 | I9: 0
A10: 45413 | B10: 0 | C10: 0 | D10: 0 | E10: 0 | G10: 0 | I10: 0
A11: 45444 | B11: 0 | C11: 0 | D11: 0 | E11: 0 | G11: 0 | I11: 0
A12: 45474 | B12: 0 | C12: 0 | D12: 0 | E12: 0 | F12: 0 | G12: 0 | I12: 0
A13: 45505 | B13: 0 | C13: 0 | E13: 0 | G13: 0 | I13: 0
A14: 45536 | B14: 0 | E14: 0 | G14: 0 | I14: 0
A15: 45566 | B15: 0 | E15: 0 | G15: 0 | I15: 0
A16: 45597 | B16: 0 | E16: 0 | G16: 0 | I16: 0
A17: 45689 | B17: 0 | D17: 0 | E17: 0 | G17: 0 | I17: 0
A18: 45717 | B18: 0 | D18: 0 | E18: 0 | G18: 0 | I18: 0
A19: 45748 | B19: 0 | C19: 0 | D19: 0 | E19: 0 | G19: 0 | I19: 0
A20: 45778 | B20: 0 | D20: 0 | E20: 0 | G20: 0 | I20: 0
A21: 45809 | B21: 0 | D21: 0 | E21: 0 | G21: 0 | I21: 0
A22: 45839 | B22: 0 | C22: 0 | D22: 0 | G22: 0 | I22: 0
A23: 45870 | B23: 0 | E23: 0 | G23: 0 | I23: 0
A24: 45901 | B24: 0 | E24: 0 | G24: 0 | H24: 0 | I24: 0
A25: 45931 | B25: 0 | G25: 0 | I25: 0
A26: 45962 | B26: 0 | G26: 0 | I26: 0
A27: 45992 | B27: 0 | I27: 0
A28: 46023 | E28: -20 | I28: -20
A29: Grand Total | B29: 0 | C29: 0 | D29: 0 | E29: -20 | F29: 0 | G29: 0 | H29: 0 | I29: -20
J31: Player - Places
M32: Outcome | N32: Loss | O32: Pending | P32: Place | Q32: Win | R32: Grand Total
J33: Place Terms | K33: Player | L33: Price | M33: Result
M34: T8 | N34: 0 | R34: 0
L35: 11-1 | N35: 0 | R35: 0
K36: Jason Day | N36: 0 | R36: 0
J37: 1/3 Top 2 | N37: 0 | R37: 0
M38: N/A | N38: 0 | R38: 0
L39: 45-1 | N39: 0 | R39: 0
K40: Ben Griffin | N40: 0 | R40: 0
M41: N/A | N41: 0 | R41: 0
...

Sheet 2025
A1: Golf Betting Record - 2025
A2: Tour/Majors | B2: DP World Tour | C2: LIV | D2: Majors | E2: Multiple | F2: Olympics | G2: PGA Tour | H2: Ryder Cup | I2: Grand Total
A3: Date (YM) | B3: Profit/Loss (Sum)
A4: 45078 | D4: 0 | I4: 0
A5: 45108 | D5: 0 | E5: 0 | I5: 0
A6: 45170 | B6: 0 | C6: 0 | H6: 0 | I6: 0
A7: 45200 | B7: 0 | E7: 0 | I7: 0
A8: 45352 | E8: 0 | G8: 0 | I8: 0
A9: 45383 | B9: 0 | C9: 0 | D9: 0 | E9: 0 | G9: 0 | I9: 0
A10: 45413 | B10: 0 | C10: 0 | D10: 0 | E10: 0 | G10: 0 | I10: 0
A11: 45444 | B11: 0 | C11: 0 | D11: 0 | E11: 0 | G11: 0 | I11: 0
A12: 45474 | B12: 0 | C12: 0 | D12: 0 | E12: 0 | F12: 0 | G12: 0 | I12: 0
A13: 45505 | B13: 0 | C13: 0 | E13: 0 | G13: 0 | I13: 0
A14: 45536 | B14: 0 | E14: 0 | G14: 0 | I14: 0
A15: 45566 | B15: 0 | E15: 0 | G15: 0 | I15: 0
A16: 45597 | B16: 0 | E16: 0 | G16: 0 | I16: 0
A17: 45689 | B17: -35 | D17: -5 | E17: -9.59 | G17: -60.75 | I17: -110.34
A18: 45717 | B18: 6.25 | D18: -10 | E18: -26.91 | G18: 54.38 | I18: 23.72
A19: 45748 | B19: -32.25 | C19: -10 | D19: 184.77 | E19: -5.5 | G19: -5.33 | I19: 131.69
A20: 45778 | B20: -73.5 | D20: -6.92 | E20: -2.5 | G20: 56.3 | I20: -26.62
A21: 45809 | B21: 39.25 | D21: 21 | E21: -5 | G21: 235.73 | I21: 290.98
A22: 45839 | B22: 32.5 | C22: -20 | D22: -72.5 | G22: 146.75 | I22: 86.75
A23: 45870 | B23: -53.25 | E23: -2.5 | G23: -117.5 | I23: -173.25
A24: 45901 | B24: 67.75 | E24: -2 | G24: 14.5 | H24: 42.5 | I24: 122.75
A25: 45931 | B25: -32 | G25: 0 | I25: -32
A26: 45962 | B26: -62.5 | G26: -16.93 | I26: -79.43
A27: 45992 | B27: 170.25 | I27: 170.25
A28: Grand Total | B28: 27.5 | C28: -30 | D28: 111.35 | E28: -54 | F28: 0 | G28: 307.15 | H28: 42.5 | I28: 404.5
J30: 2025 - Combined Outright & multiples
J31: Category | K31: Total
J32: DP World Tour | K32: 27.5
J33: Majors | K33: 111.35
J34: PGA Tour | K34: 307.15
J35: Multiple | K35: -54
J36: LIV | K36: -30
K37: 404.5
L39: Player - Places
O40: Outcome | P40: Loss | Q40: Pending | R40: Place | S40: Win | T40: Grand Total
L41: Place Terms | M41: Player | N41: Price | O41: Result | R41: Return (Sum)
O42: T8 | P42: 0 | T42: 0
...

Sheet 2024
A1: Golf Betting Record - 2024
A2: Tour/Majors | B2: DP World Tour | C2: LIV | D2: Majors | E2: Multiple | F2: Olympics | G2: PGA Tour | H2: Ryder Cup | I2: Grand Total
A3: Date (YM) | B3: Profit/Loss (Sum)
A4: 45078 | D4: 0 | I4: 0
A5: 45108 | D5: 0 | E5: 0 | I5: 0
A6: 45170 | B6: 0 | C6: 0 | H6: 0 | I6: 0
A7: 45200 | B7: 0 | E7: 0 | I7: 0
A8: 45352 | E8: -5 | G8: 71.88 | I8: 66.88
A9: 45383 | B9: -32.5 | C9: -27.9 | D9: 87.5 | E9: 4.92 | G9: -33.75 | I9: -1.73
A10: 45413 | B10: -20 | C10: -2.5 | D10: -45.37 | E10: -25 | G10: 41.17 | I10: -51.7
A11: 45444 | B11: 175.5 | C11: -27.5 | D11: -12.5 | E11: -15 | G11: 102.5 | I11: 223
A12: 45474 | B12: -12.5 | C12: -40 | D12: 126.43 | E12: -5 | F12: -24.37 | G12: 87.5 | I12: 132.06
A13: 45505 | B13: 9.03 | C13: -10 | E13: -9.88 | G13: 145 | I13: 134.15
A14: 45536 | B14: -165.5 | E14: 6.09 | G14: -59.2 | I14: -218.61
A15: 45566 | B15: -54.5 | E15: 3.69 | G15: -8.58 | I15: -59.39
A16: 45597 | B16: 28 | E16: -3 | G16: -45 | I16: -20
A17: 45689 | G17: 0 | I17: 0
A18: Grand Total | B18: -72.47 | C18: -107.9 | D18: 156.06 | E18: -48.18 | F18: -24.37 | G18: 301.52 | H18: 0 | I18: 204.66
J20: 2024 - Combined Outright & multiples
J21: Category | K21: Total
J22: DP World Tour | K22: -72.47
J23: LIV | K23: -107.9
J24: Majors | K24: 156.06
J25: PGA Tour | K25: 301.52
J26: Multiple | K26: -48.18
J27: Olympics | K27: -24.37
K28: {=SUM(K22:K27)} -> 204.66
L30: Monthly ROI%
L31: Month | M31: Return On Investment
L32: {='ROI%'!$A$7} -> 45352 | M32: 4.4586667
L33: {='ROI%'!$A$8} -> 45383 | M33: -0.0085432099
L34: {='ROI%'!$A$9} -> 45413 | M34: -0.23770115
L35: 45444 | M35: 1.0022472
L36: 45474 | M36: 0.49833962
L37: 45505 | M37: 0.62256358
L38: 45536 | M38: -5.8156425
L39: 45566 | M39: -0.57879349
L40: 45597 | M40: -0.31746032
N42: Yearly ROI%
N43: Year
...

Sheet 2023
A1: Golf Betting Record - 2023
A2: Tour/Majors | B2: DP World Tour | C2: LIV | D2: Majors | E2: Multiple | F2: PGA Tour | G2: Ryder Cup | H2: Grand Total
A3: Date (YM) | B3: Profit/Loss (Sum)
A4: 45078 | D4: 22.5 | H4: 22.5
A5: 45108 | D5: -30 | E5: -11.35 | H5: -41.35
A6: 45170 | B6: 306.59 | C6: 120 | G6: 63.25 | H6: 489.84
A7: 45200 | B7: -10 | E7: -10 | H7: -20
A8: 45352 | E8: 0 | F8: 0 | H8: 0
A9: 45383 | B9: 0 | C9: 0 | D9: 0 | E9: 0 | F9: 0 | H9: 0
A10: 45413 | B10: 0 | C10: 0 | D10: 0 | E10: 0 | F10: 0 | H10: 0
A11: 45444 | B11: 0 | C11: 0 | D11: 0 | E11: 0 | F11: 0 | H11: 0
A12: 45474 | B12: 0 | C12: 0 | F12: 0 | H12: 0
A13: Grand Total | B13: 296.59 | C13: 120 | D13: -7.5 | E13: -21.35 | F13: 0 | G13: 63.25 | H13: 450.99
I15: Monthly ROI%
I16: Month | J16: Return On Investment
I17: {='ROI%'!$A$3} -> 45078 | J17: 1.125
I18: {='ROI%'!$A$4} -> 45108 | J18: -0.75181818
I19: {='ROI%'!$A$5} -> 45170 | J19: 4.657602
I20: {='ROI%'!$A$6} -> 45200 | J20: -1
K22: Yearly ROI%
K23: Year
K24: {='ROI%'!$L$75} -> 44927 | L24: 2.2530349
M26: Player - Wins
O27: Outcome | P27: Loss | Q27: Pending | R27: Place | S27: Win | T27: Grand Total
M28: Place Terms | N28: Player | O28: Price | S28: Return (Sum)
O29: 45301 | P29: 0 | T29: 0
N30: Nick Taylor / Adam Hadwin | P30: 0 | T30: 0
O31: 40-1 | P31: 0 | T31: 0
N32: Robert MacIntyre | P32: 0 | T32: 0
M33: 1/4 Top 3 | P33: 0 | T33: 0
O34: 20-1 | Q34: 0 | T34: 0
O35: 40-1 | S35: 0 | T35: 0
N36: Akshay Bhatia | Q36: 0 | S36: 0 | T36: 0
O37: 35-1 | P37: 0 | T37: 0
N38: Brooks Koepka | P38: 0 | T38: 0
O39: 75-1 | P39: 0 | T39: 0
N40: Davis Riley | P40: 0 | T40: 0
O41: 45299 | P41: 0 | T41: 0
N42: Joaquin Niemann | P42: 0 | T42: 0
O43: 45307 | P43: 0 | T43: 0
...

Sheet Schedule
B2: Start Date
C3: Start Date | D3: Tournament | E3: Tour | F3: Venue/Location | G3: Notes
B4: 24/11/2025
C5: 24/11/2025 | D5: BMW Australian PGA Championship | E5: DP World Tour | F5: Royal Queensland GC, Brisbane, Australia
B6: 01/12/2025
C7: 01/12/2025 | D7: Australian Open | E7: DP World Tour | F7: Royal Melbourne GC, Melbourne, Australia
C8: 01/12/2025 | D8: Nedbank Golf Challenge | E8: DP World Tour | F8: Gary Player CC, Sun City, South Africa
B9: 08/12/2025
C10: 08/12/2025 | D10: Alfred Dunhill Championship | E10: DP World Tour | F10: Royal Johannesburg Club, Johannesburg, South Africa
B11: 15/12/2025
C12: 15/12/2025 | D12: AfrAsia Bank Mauritius Open | E12: DP World Tour | F12: Heritage La Réserve Golf Links, Mauritius
B13: 05/01/2026
C14: 05/01/2026 | D14: The Sentry | E14: PGA Tour | F14: Plantation Course, Kapalua Resort, Maui, Hawaii | G14: Event cancelled
B15: 12/01/2026
